[2024-06-07 16:07:54,129][root][INFO] - label_values: [[0, 0]]
[2024-06-07 16:07:54,129][flwr][WARNING] - DEPRECATED FEATURE: flwr.client.start_numpy_client() is deprecated.
	Instead, use `flwr.client.start_client()` by ensuring you first call the `.to_client()` method as shown below:
	flwr.client.start_client(
		server_address='<IP>:<PORT>',
		client=FlowerClient().to_client(), # <-- where FlowerClient is of type flwr.client.NumPyClient object
	)
	Using `start_numpy_client()` is deprecated.
            This is a deprecated feature. It will be removed
            entirely in future versions of Flower.
[32mINFO[39m:     127.0.0.1:43842 - "[1mGET /online HTTP/1.1[22m" [32m200 OK
[2024-06-07 16:07:54,142][flwr][DEBUG] - Opened insecure gRPC connection (no certificates were passed)
[2024-06-07 16:07:54,143][flwr][DEBUG] - ChannelConnectivity.IDLE
[2024-06-07 16:07:54,145][flwr][DEBUG] - ChannelConnectivity.CONNECTING
[2024-06-07 16:07:54,149][flwr][DEBUG] - ChannelConnectivity.READY
[2024-06-07 16:07:54,217][flwr][INFO] -
[2024-06-07 16:07:54,218][flwr][INFO] - [RUN 0, ROUND ]
[2024-06-07 16:07:54,218][flwr][INFO] - Received: train message 729652e1-fbcf-4c7f-944f-42b133ac4aee
config: {'batch_size': 128, 'local_epochs': 5, 'num_rounds': 5}
Starting training...
Epoch 1/5, Loss: 18.3054
Epoch 1/5, Validation Loss: 18.8210
[2024-06-07 16:07:54,319][flwr][ERROR] - Client raised an exception.
Traceback (most recent call last):
  File "/home/ccl/anaconda3/envs/isenv/lib/python3.11/site-packages/flwr/client/app.py", line 496, in _start_client_internal
    reply_message = client_app(message=message, context=context)
                    ^^^^^^^^^^^^^^^^^^^^^^^^^^^^^^^^^^^^^^^^^^^^
  File "/home/ccl/anaconda3/envs/isenv/lib/python3.11/site-packages/flwr/client/client_app.py", line 98, in __call__
    return self._call(message, context)
           ^^^^^^^^^^^^^^^^^^^^^^^^^^^^
  File "/home/ccl/anaconda3/envs/isenv/lib/python3.11/site-packages/flwr/client/client_app.py", line 81, in ffn
    out_message = handle_legacy_message_from_msgtype(
                  ^^^^^^^^^^^^^^^^^^^^^^^^^^^^^^^^^^^
  File "/home/ccl/anaconda3/envs/isenv/lib/python3.11/site-packages/flwr/client/message_handler/message_handler.py", line 130, in handle_legacy_message_from_msgtype
    fit_res = maybe_call_fit(
              ^^^^^^^^^^^^^^^
  File "/home/ccl/anaconda3/envs/isenv/lib/python3.11/site-packages/flwr/client/client.py", line 234, in maybe_call_fit
    return client.fit(fit_ins)
           ^^^^^^^^^^^^^^^^^^^
  File "/home/ccl/anaconda3/envs/isenv/lib/python3.11/site-packages/flwr/client/numpy_client.py", line 238, in _fit
    results = self.numpy_client.fit(parameters, ins.config)  # type: ignore
              ^^^^^^^^^^^^^^^^^^^^^^^^^^^^^^^^^^^^^^^^^^^^^
  File "/home/ccl/anaconda3/envs/isenv/lib/python3.11/site-packages/fedops/client/client_fl.py", line 135, in fit
    trained_model = self.train_torch(self.model, self.train_loader, self.val_loader, epochs)
                    ^^^^^^^^^^^^^^^^^^^^^^^^^^^^^^^^^^^^^^^^^^^^^^^^^^^^^^^^^^^^^^^^^^^^^^^^
  File "/home/ccl/Desktop/isfolder/issrc/fedops/FedOps-ADMET2/models.py", line 56, in custom_train_torch
    if val_loss < best_val_loss:
                  ^^^^^^^^^^^^^
UnboundLocalError: cannot access local variable 'best_val_loss' where it is not associated with a value
[2024-06-07 16:07:54,352][flwr][DEBUG] - gRPC channel closed
[2024-06-07 16:07:54,370][root][INFO] - notify_fail start
[2024-06-07 16:07:54,391][root][ERROR] - trainFin
[93mWARNING [39m:   DEPRECATED FEATURE: flwr.client.start_numpy_client() is deprecated.
	Instead, use `flwr.client.start_client()` by ensuring you first call the `.to_client()` method as shown below:
	flwr.client.start_client(
		server_address='<IP>:<PORT>',
		client=FlowerClient().to_client(), # <-- where FlowerClient is of type flwr.client.NumPyClient object
	)
	Using `start_numpy_client()` is deprecated.
            This is a deprecated feature. It will be removed
            entirely in future versions of Flower.
[92mINFO [39m:
[92mINFO [39m:      [RUN 0, ROUND ]
[92mINFO [39m:      Received: train message 729652e1-fbcf-4c7f-944f-42b133ac4aee
100%|â–ˆâ–ˆâ–ˆâ–ˆâ–ˆâ–ˆâ–ˆâ–ˆâ–ˆâ–ˆâ–ˆâ–ˆâ–ˆâ–ˆâ–ˆâ–ˆâ–ˆâ–ˆâ–ˆâ–ˆâ–ˆâ–ˆâ–ˆâ–ˆâ–ˆâ–ˆâ–ˆâ–ˆâ–ˆâ–ˆâ–ˆâ–ˆâ–ˆâ–ˆâ–ˆâ–ˆâ–ˆâ–ˆâ–ˆâ–ˆâ–ˆâ–ˆâ–ˆâ–ˆâ–ˆâ–ˆâ–ˆâ–ˆâ–ˆâ–ˆâ–ˆâ–ˆâ–ˆâ–ˆâ–ˆâ–ˆâ–ˆâ–ˆâ–ˆâ–ˆâ–ˆâ–ˆâ–ˆâ–ˆâ–ˆâ–ˆâ–ˆâ–ˆâ–ˆâ–ˆ| 2/2 [00:00<00:00, 26.28it/s]
[91mERROR [39m:     Client raised an exception.
Traceback (most recent call last):
  File "/home/ccl/anaconda3/envs/isenv/lib/python3.11/site-packages/flwr/client/app.py", line 496, in _start_client_internal
    reply_message = client_app(message=message, context=context)
                    ^^^^^^^^^^^^^^^^^^^^^^^^^^^^^^^^^^^^^^^^^^^^
  File "/home/ccl/anaconda3/envs/isenv/lib/python3.11/site-packages/flwr/client/client_app.py", line 98, in __call__
    return self._call(message, context)
           ^^^^^^^^^^^^^^^^^^^^^^^^^^^^
  File "/home/ccl/anaconda3/envs/isenv/lib/python3.11/site-packages/flwr/client/client_app.py", line 81, in ffn
    out_message = handle_legacy_message_from_msgtype(
                  ^^^^^^^^^^^^^^^^^^^^^^^^^^^^^^^^^^^
  File "/home/ccl/anaconda3/envs/isenv/lib/python3.11/site-packages/flwr/client/message_handler/message_handler.py", line 130, in handle_legacy_message_from_msgtype
    fit_res = maybe_call_fit(
              ^^^^^^^^^^^^^^^
  File "/home/ccl/anaconda3/envs/isenv/lib/python3.11/site-packages/flwr/client/client.py", line 234, in maybe_call_fit
    return client.fit(fit_ins)
           ^^^^^^^^^^^^^^^^^^^
  File "/home/ccl/anaconda3/envs/isenv/lib/python3.11/site-packages/flwr/client/numpy_client.py", line 238, in _fit
    results = self.numpy_client.fit(parameters, ins.config)  # type: ignore
              ^^^^^^^^^^^^^^^^^^^^^^^^^^^^^^^^^^^^^^^^^^^^^
  File "/home/ccl/anaconda3/envs/isenv/lib/python3.11/site-packages/fedops/client/client_fl.py", line 135, in fit
    trained_model = self.train_torch(self.model, self.train_loader, self.val_loader, epochs)
                    ^^^^^^^^^^^^^^^^^^^^^^^^^^^^^^^^^^^^^^^^^^^^^^^^^^^^^^^^^^^^^^^^^^^^^^^^
  File "/home/ccl/Desktop/isfolder/issrc/fedops/FedOps-ADMET2/models.py", line 56, in custom_train_torch
    if val_loss < best_val_loss:
                  ^^^^^^^^^^^^^
UnboundLocalError: cannot access local variable 'best_val_loss' where it is not associated with a value
--- Logging error ---
Traceback (most recent call last):
  File "/home/ccl/anaconda3/envs/isenv/lib/python3.11/site-packages/fedops/client/app.py", line 123, in fl_client_start
    await loop.run_in_executor(None, client_start)
  File "/home/ccl/anaconda3/envs/isenv/lib/python3.11/concurrent/futures/thread.py", line 58, in run
    result = self.fn(*self.args, **self.kwargs)
             ^^^^^^^^^^^^^^^^^^^^^^^^^^^^^^^^^^
  File "/home/ccl/anaconda3/envs/isenv/lib/python3.11/site-packages/flwr/client/app.py", line 643, in start_numpy_client
    start_client(
  File "/home/ccl/anaconda3/envs/isenv/lib/python3.11/site-packages/flwr/client/app.py", line 291, in start_client
    _start_client_internal(
  File "/home/ccl/anaconda3/envs/isenv/lib/python3.11/site-packages/flwr/client/app.py", line 503, in _start_client_internal
    raise ex
  File "/home/ccl/anaconda3/envs/isenv/lib/python3.11/site-packages/flwr/client/app.py", line 496, in _start_client_internal
    reply_message = client_app(message=message, context=context)
                    ^^^^^^^^^^^^^^^^^^^^^^^^^^^^^^^^^^^^^^^^^^^^
  File "/home/ccl/anaconda3/envs/isenv/lib/python3.11/site-packages/flwr/client/client_app.py", line 98, in __call__
    return self._call(message, context)
           ^^^^^^^^^^^^^^^^^^^^^^^^^^^^
  File "/home/ccl/anaconda3/envs/isenv/lib/python3.11/site-packages/flwr/client/client_app.py", line 81, in ffn
    out_message = handle_legacy_message_from_msgtype(
                  ^^^^^^^^^^^^^^^^^^^^^^^^^^^^^^^^^^^
  File "/home/ccl/anaconda3/envs/isenv/lib/python3.11/site-packages/flwr/client/message_handler/message_handler.py", line 130, in handle_legacy_message_from_msgtype
    fit_res = maybe_call_fit(
              ^^^^^^^^^^^^^^^
  File "/home/ccl/anaconda3/envs/isenv/lib/python3.11/site-packages/flwr/client/client.py", line 234, in maybe_call_fit
    return client.fit(fit_ins)
           ^^^^^^^^^^^^^^^^^^^
  File "/home/ccl/anaconda3/envs/isenv/lib/python3.11/site-packages/flwr/client/numpy_client.py", line 238, in _fit
    results = self.numpy_client.fit(parameters, ins.config)  # type: ignore
              ^^^^^^^^^^^^^^^^^^^^^^^^^^^^^^^^^^^^^^^^^^^^^
  File "/home/ccl/anaconda3/envs/isenv/lib/python3.11/site-packages/fedops/client/client_fl.py", line 135, in fit
    trained_model = self.train_torch(self.model, self.train_loader, self.val_loader, epochs)
                    ^^^^^^^^^^^^^^^^^^^^^^^^^^^^^^^^^^^^^^^^^^^^^^^^^^^^^^^^^^^^^^^^^^^^^^^^
  File "/home/ccl/Desktop/isfolder/issrc/fedops/FedOps-ADMET2/models.py", line 56, in custom_train_torch
    if val_loss < best_val_loss:
                  ^^^^^^^^^^^^^
UnboundLocalError: cannot access local variable 'best_val_loss' where it is not associated with a value
During handling of the above exception, another exception occurred:
Traceback (most recent call last):
  File "/home/ccl/anaconda3/envs/isenv/lib/python3.11/logging/__init__.py", line 1110, in emit
    msg = self.format(record)
          ^^^^^^^^^^^^^^^^^^^
  File "/home/ccl/anaconda3/envs/isenv/lib/python3.11/logging/__init__.py", line 953, in format
    return fmt.format(record)
           ^^^^^^^^^^^^^^^^^^
  File "/home/ccl/anaconda3/envs/isenv/lib/python3.11/logging/__init__.py", line 687, in format
    record.message = record.getMessage()
                     ^^^^^^^^^^^^^^^^^^^
  File "/home/ccl/anaconda3/envs/isenv/lib/python3.11/logging/__init__.py", line 377, in getMessage
    msg = msg % self.args
          ~~~~^~~~~~~~~~~
TypeError: not all arguments converted during string formatting
Call stack:
  File "/home/ccl/Desktop/isfolder/issrc/fedops/FedOps-ADMET2/client_main.py", line 88, in <module>
    main()
  File "/home/ccl/anaconda3/envs/isenv/lib/python3.11/site-packages/hydra/main.py", line 94, in decorated_main
    _run_hydra(
  File "/home/ccl/anaconda3/envs/isenv/lib/python3.11/site-packages/hydra/_internal/utils.py", line 394, in _run_hydra
    _run_app(
  File "/home/ccl/anaconda3/envs/isenv/lib/python3.11/site-packages/hydra/_internal/utils.py", line 457, in _run_app
    run_and_report(
  File "/home/ccl/anaconda3/envs/isenv/lib/python3.11/site-packages/hydra/_internal/utils.py", line 220, in run_and_report
    return func()
  File "/home/ccl/anaconda3/envs/isenv/lib/python3.11/site-packages/hydra/_internal/utils.py", line 458, in <lambda>
    lambda: hydra.run(
  File "/home/ccl/anaconda3/envs/isenv/lib/python3.11/site-packages/hydra/_internal/hydra.py", line 119, in run
    ret = run_job(
  File "/home/ccl/anaconda3/envs/isenv/lib/python3.11/site-packages/hydra/core/utils.py", line 186, in run_job
    ret.return_value = task_function(task_cfg)
  File "/home/ccl/Desktop/isfolder/issrc/fedops/FedOps-ADMET2/client_main.py", line 84, in main
    fl_client.start()
  File "/home/ccl/anaconda3/envs/isenv/lib/python3.11/site-packages/fedops/client/app.py", line 202, in start
    uvicorn.run(self.app, host='0.0.0.0', port=self.client_port)
  File "/home/ccl/anaconda3/envs/isenv/lib/python3.11/site-packages/uvicorn/main.py", line 587, in run
    server.run()
  File "/home/ccl/anaconda3/envs/isenv/lib/python3.11/site-packages/uvicorn/server.py", line 61, in run
    return asyncio.run(self.serve(sockets=sockets))
  File "/home/ccl/anaconda3/envs/isenv/lib/python3.11/asyncio/runners.py", line 190, in run
    return runner.run(main)
  File "/home/ccl/anaconda3/envs/isenv/lib/python3.11/asyncio/runners.py", line 118, in run
    return self._loop.run_until_complete(task)
  File "/home/ccl/anaconda3/envs/isenv/lib/python3.11/site-packages/uvicorn/protocols/http/httptools_impl.py", line 426, in run_asgi
    result = await app(  # type: ignore[func-returns-value]
  File "/home/ccl/anaconda3/envs/isenv/lib/python3.11/site-packages/uvicorn/middleware/proxy_headers.py", line 84, in __call__
    return await self.app(scope, receive, send)
  File "/home/ccl/anaconda3/envs/isenv/lib/python3.11/site-packages/fastapi/applications.py", line 1054, in __call__
    await super().__call__(scope, receive, send)
  File "/home/ccl/anaconda3/envs/isenv/lib/python3.11/site-packages/starlette/applications.py", line 116, in __call__
    await self.middleware_stack(scope, receive, send)
  File "/home/ccl/anaconda3/envs/isenv/lib/python3.11/site-packages/starlette/middleware/errors.py", line 164, in __call__
    await self.app(scope, receive, _send)
  File "/home/ccl/anaconda3/envs/isenv/lib/python3.11/site-packages/starlette/middleware/exceptions.py", line 62, in __call__
    await wrap_app_handling_exceptions(self.app, conn)(scope, receive, send)
  File "/home/ccl/anaconda3/envs/isenv/lib/python3.11/site-packages/starlette/_exception_handler.py", line 44, in wrapped_app
    await app(scope, receive, sender)
  File "/home/ccl/anaconda3/envs/isenv/lib/python3.11/site-packages/starlette/routing.py", line 746, in __call__
    await route.handle(scope, receive, send)
  File "/home/ccl/anaconda3/envs/isenv/lib/python3.11/site-packages/starlette/routing.py", line 288, in handle
    await self.app(scope, receive, send)
  File "/home/ccl/anaconda3/envs/isenv/lib/python3.11/site-packages/starlette/routing.py", line 75, in app
    await wrap_app_handling_exceptions(app, request)(scope, receive, send)
  File "/home/ccl/anaconda3/envs/isenv/lib/python3.11/site-packages/starlette/_exception_handler.py", line 44, in wrapped_app
    await app(scope, receive, sender)
  File "/home/ccl/anaconda3/envs/isenv/lib/python3.11/site-packages/starlette/routing.py", line 73, in app
    await response(scope, receive, send)
  File "/home/ccl/anaconda3/envs/isenv/lib/python3.11/site-packages/starlette/responses.py", line 156, in __call__
    await self.background()
  File "/home/ccl/anaconda3/envs/isenv/lib/python3.11/site-packages/starlette/background.py", line 43, in __call__
    await task()
  File "/home/ccl/anaconda3/envs/isenv/lib/python3.11/site-packages/starlette/background.py", line 26, in __call__
    await self.func(*self.args, **self.kwargs)
  File "/home/ccl/anaconda3/envs/isenv/lib/python3.11/site-packages/fedops/client/app.py", line 159, in fl_client_start
    logging.info('[E][PC0002] learning', e)
Message: '[E][PC0002] learning'
Arguments: (UnboundLocalError("cannot access local variable 'best_val_loss' where it is not associated with a value"),)
--- Logging error ---
Traceback (most recent call last):
  File "/home/ccl/anaconda3/envs/isenv/lib/python3.11/site-packages/fedops/client/app.py", line 123, in fl_client_start
    await loop.run_in_executor(None, client_start)
  File "/home/ccl/anaconda3/envs/isenv/lib/python3.11/concurrent/futures/thread.py", line 58, in run
    result = self.fn(*self.args, **self.kwargs)
             ^^^^^^^^^^^^^^^^^^^^^^^^^^^^^^^^^^
  File "/home/ccl/anaconda3/envs/isenv/lib/python3.11/site-packages/flwr/client/app.py", line 643, in start_numpy_client
    start_client(
  File "/home/ccl/anaconda3/envs/isenv/lib/python3.11/site-packages/flwr/client/app.py", line 291, in start_client
    _start_client_internal(
  File "/home/ccl/anaconda3/envs/isenv/lib/python3.11/site-packages/flwr/client/app.py", line 503, in _start_client_internal
    raise ex
  File "/home/ccl/anaconda3/envs/isenv/lib/python3.11/site-packages/flwr/client/app.py", line 496, in _start_client_internal
    reply_message = client_app(message=message, context=context)
                    ^^^^^^^^^^^^^^^^^^^^^^^^^^^^^^^^^^^^^^^^^^^^
  File "/home/ccl/anaconda3/envs/isenv/lib/python3.11/site-packages/flwr/client/client_app.py", line 98, in __call__
    return self._call(message, context)
           ^^^^^^^^^^^^^^^^^^^^^^^^^^^^
  File "/home/ccl/anaconda3/envs/isenv/lib/python3.11/site-packages/flwr/client/client_app.py", line 81, in ffn
    out_message = handle_legacy_message_from_msgtype(
                  ^^^^^^^^^^^^^^^^^^^^^^^^^^^^^^^^^^^
  File "/home/ccl/anaconda3/envs/isenv/lib/python3.11/site-packages/flwr/client/message_handler/message_handler.py", line 130, in handle_legacy_message_from_msgtype
    fit_res = maybe_call_fit(
              ^^^^^^^^^^^^^^^
  File "/home/ccl/anaconda3/envs/isenv/lib/python3.11/site-packages/flwr/client/client.py", line 234, in maybe_call_fit
    return client.fit(fit_ins)
           ^^^^^^^^^^^^^^^^^^^
  File "/home/ccl/anaconda3/envs/isenv/lib/python3.11/site-packages/flwr/client/numpy_client.py", line 238, in _fit
    results = self.numpy_client.fit(parameters, ins.config)  # type: ignore
              ^^^^^^^^^^^^^^^^^^^^^^^^^^^^^^^^^^^^^^^^^^^^^
  File "/home/ccl/anaconda3/envs/isenv/lib/python3.11/site-packages/fedops/client/client_fl.py", line 135, in fit
    trained_model = self.train_torch(self.model, self.train_loader, self.val_loader, epochs)
                    ^^^^^^^^^^^^^^^^^^^^^^^^^^^^^^^^^^^^^^^^^^^^^^^^^^^^^^^^^^^^^^^^^^^^^^^^
  File "/home/ccl/Desktop/isfolder/issrc/fedops/FedOps-ADMET2/models.py", line 56, in custom_train_torch
    if val_loss < best_val_loss:
                  ^^^^^^^^^^^^^
UnboundLocalError: cannot access local variable 'best_val_loss' where it is not associated with a value
During handling of the above exception, another exception occurred:
Traceback (most recent call last):
  File "/home/ccl/anaconda3/envs/isenv/lib/python3.11/logging/__init__.py", line 1110, in emit
    msg = self.format(record)
          ^^^^^^^^^^^^^^^^^^^
  File "/home/ccl/anaconda3/envs/isenv/lib/python3.11/logging/__init__.py", line 953, in format
    return fmt.format(record)
           ^^^^^^^^^^^^^^^^^^
  File "/home/ccl/anaconda3/envs/isenv/lib/python3.11/logging/__init__.py", line 687, in format
    record.message = record.getMessage()
                     ^^^^^^^^^^^^^^^^^^^
  File "/home/ccl/anaconda3/envs/isenv/lib/python3.11/logging/__init__.py", line 377, in getMessage
    msg = msg % self.args
          ~~~~^~~~~~~~~~~
TypeError: not all arguments converted during string formatting
Call stack:
  File "/home/ccl/Desktop/isfolder/issrc/fedops/FedOps-ADMET2/client_main.py", line 88, in <module>
    main()
  File "/home/ccl/anaconda3/envs/isenv/lib/python3.11/site-packages/hydra/main.py", line 94, in decorated_main
    _run_hydra(
  File "/home/ccl/anaconda3/envs/isenv/lib/python3.11/site-packages/hydra/_internal/utils.py", line 394, in _run_hydra
    _run_app(
  File "/home/ccl/anaconda3/envs/isenv/lib/python3.11/site-packages/hydra/_internal/utils.py", line 457, in _run_app
    run_and_report(
  File "/home/ccl/anaconda3/envs/isenv/lib/python3.11/site-packages/hydra/_internal/utils.py", line 220, in run_and_report
    return func()
  File "/home/ccl/anaconda3/envs/isenv/lib/python3.11/site-packages/hydra/_internal/utils.py", line 458, in <lambda>
    lambda: hydra.run(
  File "/home/ccl/anaconda3/envs/isenv/lib/python3.11/site-packages/hydra/_internal/hydra.py", line 119, in run
    ret = run_job(
  File "/home/ccl/anaconda3/envs/isenv/lib/python3.11/site-packages/hydra/core/utils.py", line 186, in run_job
    ret.return_value = task_function(task_cfg)
  File "/home/ccl/Desktop/isfolder/issrc/fedops/FedOps-ADMET2/client_main.py", line 84, in main
    fl_client.start()
  File "/home/ccl/anaconda3/envs/isenv/lib/python3.11/site-packages/fedops/client/app.py", line 202, in start
    uvicorn.run(self.app, host='0.0.0.0', port=self.client_port)
  File "/home/ccl/anaconda3/envs/isenv/lib/python3.11/site-packages/uvicorn/main.py", line 587, in run
    server.run()
  File "/home/ccl/anaconda3/envs/isenv/lib/python3.11/site-packages/uvicorn/server.py", line 61, in run
    return asyncio.run(self.serve(sockets=sockets))
  File "/home/ccl/anaconda3/envs/isenv/lib/python3.11/asyncio/runners.py", line 190, in run
    return runner.run(main)
  File "/home/ccl/anaconda3/envs/isenv/lib/python3.11/asyncio/runners.py", line 118, in run
    return self._loop.run_until_complete(task)
  File "/home/ccl/anaconda3/envs/isenv/lib/python3.11/site-packages/uvicorn/protocols/http/httptools_impl.py", line 426, in run_asgi
    result = await app(  # type: ignore[func-returns-value]
  File "/home/ccl/anaconda3/envs/isenv/lib/python3.11/site-packages/uvicorn/middleware/proxy_headers.py", line 84, in __call__
    return await self.app(scope, receive, send)
  File "/home/ccl/anaconda3/envs/isenv/lib/python3.11/site-packages/fastapi/applications.py", line 1054, in __call__
    await super().__call__(scope, receive, send)
  File "/home/ccl/anaconda3/envs/isenv/lib/python3.11/site-packages/starlette/applications.py", line 116, in __call__
    await self.middleware_stack(scope, receive, send)
  File "/home/ccl/anaconda3/envs/isenv/lib/python3.11/site-packages/starlette/middleware/errors.py", line 164, in __call__
    await self.app(scope, receive, _send)
  File "/home/ccl/anaconda3/envs/isenv/lib/python3.11/site-packages/starlette/middleware/exceptions.py", line 62, in __call__
    await wrap_app_handling_exceptions(self.app, conn)(scope, receive, send)
  File "/home/ccl/anaconda3/envs/isenv/lib/python3.11/site-packages/starlette/_exception_handler.py", line 44, in wrapped_app
    await app(scope, receive, sender)
  File "/home/ccl/anaconda3/envs/isenv/lib/python3.11/site-packages/starlette/routing.py", line 746, in __call__
    await route.handle(scope, receive, send)
  File "/home/ccl/anaconda3/envs/isenv/lib/python3.11/site-packages/starlette/routing.py", line 288, in handle
    await self.app(scope, receive, send)
  File "/home/ccl/anaconda3/envs/isenv/lib/python3.11/site-packages/starlette/routing.py", line 75, in app
    await wrap_app_handling_exceptions(app, request)(scope, receive, send)
  File "/home/ccl/anaconda3/envs/isenv/lib/python3.11/site-packages/starlette/_exception_handler.py", line 44, in wrapped_app
    await app(scope, receive, sender)
  File "/home/ccl/anaconda3/envs/isenv/lib/python3.11/site-packages/starlette/routing.py", line 73, in app
    await response(scope, receive, send)
  File "/home/ccl/anaconda3/envs/isenv/lib/python3.11/site-packages/starlette/responses.py", line 156, in __call__
    await self.background()
  File "/home/ccl/anaconda3/envs/isenv/lib/python3.11/site-packages/starlette/background.py", line 43, in __call__
    await task()
  File "/home/ccl/anaconda3/envs/isenv/lib/python3.11/site-packages/starlette/background.py", line 26, in __call__
    await self.func(*self.args, **self.kwargs)
  File "/home/ccl/anaconda3/envs/isenv/lib/python3.11/site-packages/fedops/client/app.py", line 159, in fl_client_start
    logging.info('[E][PC0002] learning', e)
Message: '[E][PC0002] learning'
Arguments: (UnboundLocalError("cannot access local variable 'best_val_loss' where it is not associated with a value"),)
[31mERROR[39m:    Exception in ASGI application
Traceback (most recent call last):
  File "/home/ccl/anaconda3/envs/isenv/lib/python3.11/site-packages/uvicorn/protocols/http/httptools_impl.py", line 426, in run_asgi
    result = await app(  # type: ignore[func-returns-value]
             ^^^^^^^^^^^^^^^^^^^^^^^^^^^^^^^^^^^^^^^^^^^^^^
  File "/home/ccl/anaconda3/envs/isenv/lib/python3.11/site-packages/uvicorn/middleware/proxy_headers.py", line 84, in __call__
    return await self.app(scope, receive, send)
           ^^^^^^^^^^^^^^^^^^^^^^^^^^^^^^^^^^^^
  File "/home/ccl/anaconda3/envs/isenv/lib/python3.11/site-packages/fastapi/applications.py", line 1054, in __call__
    await super().__call__(scope, receive, send)
  File "/home/ccl/anaconda3/envs/isenv/lib/python3.11/site-packages/starlette/applications.py", line 116, in __call__
    await self.middleware_stack(scope, receive, send)
  File "/home/ccl/anaconda3/envs/isenv/lib/python3.11/site-packages/starlette/middleware/errors.py", line 186, in __call__
    raise exc
  File "/home/ccl/anaconda3/envs/isenv/lib/python3.11/site-packages/starlette/middleware/errors.py", line 164, in __call__
    await self.app(scope, receive, _send)
  File "/home/ccl/anaconda3/envs/isenv/lib/python3.11/site-packages/starlette/middleware/exceptions.py", line 62, in __call__
    await wrap_app_handling_exceptions(self.app, conn)(scope, receive, send)
  File "/home/ccl/anaconda3/envs/isenv/lib/python3.11/site-packages/starlette/_exception_handler.py", line 55, in wrapped_app
    raise exc
  File "/home/ccl/anaconda3/envs/isenv/lib/python3.11/site-packages/starlette/_exception_handler.py", line 44, in wrapped_app
    await app(scope, receive, sender)
  File "/home/ccl/anaconda3/envs/isenv/lib/python3.11/site-packages/starlette/routing.py", line 746, in __call__
    await route.handle(scope, receive, send)
  File "/home/ccl/anaconda3/envs/isenv/lib/python3.11/site-packages/starlette/routing.py", line 288, in handle
    await self.app(scope, receive, send)
  File "/home/ccl/anaconda3/envs/isenv/lib/python3.11/site-packages/starlette/routing.py", line 75, in app
    await wrap_app_handling_exceptions(app, request)(scope, receive, send)
  File "/home/ccl/anaconda3/envs/isenv/lib/python3.11/site-packages/starlette/_exception_handler.py", line 55, in wrapped_app
    raise exc
  File "/home/ccl/anaconda3/envs/isenv/lib/python3.11/site-packages/starlette/_exception_handler.py", line 44, in wrapped_app
    await app(scope, receive, sender)
  File "/home/ccl/anaconda3/envs/isenv/lib/python3.11/site-packages/starlette/routing.py", line 73, in app
    await response(scope, receive, send)
  File "/home/ccl/anaconda3/envs/isenv/lib/python3.11/site-packages/starlette/responses.py", line 156, in __call__
    await self.background()
  File "/home/ccl/anaconda3/envs/isenv/lib/python3.11/site-packages/starlette/background.py", line 43, in __call__
    await task()
  File "/home/ccl/anaconda3/envs/isenv/lib/python3.11/site-packages/starlette/background.py", line 26, in __call__
    await self.func(*self.args, **self.kwargs)
  File "/home/ccl/anaconda3/envs/isenv/lib/python3.11/site-packages/fedops/client/app.py", line 162, in fl_client_start
    raise e
  File "/home/ccl/anaconda3/envs/isenv/lib/python3.11/site-packages/fedops/client/app.py", line 123, in fl_client_start
    await loop.run_in_executor(None, client_start)
  File "/home/ccl/anaconda3/envs/isenv/lib/python3.11/concurrent/futures/thread.py", line 58, in run
    result = self.fn(*self.args, **self.kwargs)
             ^^^^^^^^^^^^^^^^^^^^^^^^^^^^^^^^^^
  File "/home/ccl/anaconda3/envs/isenv/lib/python3.11/site-packages/flwr/client/app.py", line 643, in start_numpy_client
    start_client(
  File "/home/ccl/anaconda3/envs/isenv/lib/python3.11/site-packages/flwr/client/app.py", line 291, in start_client
    _start_client_internal(
  File "/home/ccl/anaconda3/envs/isenv/lib/python3.11/site-packages/flwr/client/app.py", line 503, in _start_client_internal
    raise ex
  File "/home/ccl/anaconda3/envs/isenv/lib/python3.11/site-packages/flwr/client/app.py", line 496, in _start_client_internal
    reply_message = client_app(message=message, context=context)
                    ^^^^^^^^^^^^^^^^^^^^^^^^^^^^^^^^^^^^^^^^^^^^
  File "/home/ccl/anaconda3/envs/isenv/lib/python3.11/site-packages/flwr/client/client_app.py", line 98, in __call__
    return self._call(message, context)
           ^^^^^^^^^^^^^^^^^^^^^^^^^^^^
  File "/home/ccl/anaconda3/envs/isenv/lib/python3.11/site-packages/flwr/client/client_app.py", line 81, in ffn
    out_message = handle_legacy_message_from_msgtype(
                  ^^^^^^^^^^^^^^^^^^^^^^^^^^^^^^^^^^^
  File "/home/ccl/anaconda3/envs/isenv/lib/python3.11/site-packages/flwr/client/message_handler/message_handler.py", line 130, in handle_legacy_message_from_msgtype
    fit_res = maybe_call_fit(
              ^^^^^^^^^^^^^^^
  File "/home/ccl/anaconda3/envs/isenv/lib/python3.11/site-packages/flwr/client/client.py", line 234, in maybe_call_fit
    return client.fit(fit_ins)
           ^^^^^^^^^^^^^^^^^^^
  File "/home/ccl/anaconda3/envs/isenv/lib/python3.11/site-packages/flwr/client/numpy_client.py", line 238, in _fit
    results = self.numpy_client.fit(parameters, ins.config)  # type: ignore
              ^^^^^^^^^^^^^^^^^^^^^^^^^^^^^^^^^^^^^^^^^^^^^
  File "/home/ccl/anaconda3/envs/isenv/lib/python3.11/site-packages/fedops/client/client_fl.py", line 135, in fit
    trained_model = self.train_torch(self.model, self.train_loader, self.val_loader, epochs)
                    ^^^^^^^^^^^^^^^^^^^^^^^^^^^^^^^^^^^^^^^^^^^^^^^^^^^^^^^^^^^^^^^^^^^^^^^^
  File "/home/ccl/Desktop/isfolder/issrc/fedops/FedOps-ADMET2/models.py", line 56, in custom_train_torch
    if val_loss < best_val_loss:
                  ^^^^^^^^^^^^^
UnboundLocalError: cannot access local variable 'best_val_loss' where it is not associated with a value
[32mINFO[39m:     127.0.0.1:41118 - "[1mGET /online HTTP/1.1[22m" [32m200 OK
[32mINFO[39m:     127.0.0.1:44594 - "[1mGET /online HTTP/1.1[22m" [32m200 OK
[32mINFO[39m:     127.0.0.1:54368 - "[1mGET /online HTTP/1.1[22m" [32m200 OK
[32mINFO[39m:     127.0.0.1:54380 - "[1mGET /online HTTP/1.1[22m" [32m200 OK
[32mINFO[39m:     127.0.0.1:43154 - "[1mGET /online HTTP/1.1[22m" [32m200 OK
[32mINFO[39m:     127.0.0.1:47284 - "[1mGET /online HTTP/1.1[22m" [32m200 OK
[32mINFO[39m:     127.0.0.1:47292 - "[1mGET /online HTTP/1.1[22m" [32m200 OK
[32mINFO[39m:     127.0.0.1:46484 - "[1mGET /online HTTP/1.1[22m" [32m200 OK
[32mINFO[39m:     127.0.0.1:39118 - "[1mGET /online HTTP/1.1[22m" [32m200 OK
[32mINFO[39m:     127.0.0.1:39128 - "[1mGET /online HTTP/1.1[22m" [32m200 OK
[32mINFO[39m:     127.0.0.1:53746 - "[1mGET /online HTTP/1.1[22m" [32m200 OK
[32mINFO[39m:     127.0.0.1:56532 - "[1mGET /online HTTP/1.1[22m" [32m200 OK
[32mINFO[39m:     127.0.0.1:56536 - "[1mGET /online HTTP/1.1[22m" [32m200 OK
[32mINFO[39m:     127.0.0.1:46020 - "[1mGET /online HTTP/1.1[22m" [32m200 OK
[32mINFO[39m:     127.0.0.1:38444 - "[1mGET /online HTTP/1.1[22m" [32m200 OK
[32mINFO[39m:     127.0.0.1:38458 - "[1mGET /online HTTP/1.1[22m" [32m200 OK
[32mINFO[39m:     127.0.0.1:56234 - "[1mGET /online HTTP/1.1[22m" [32m200 OK
[32mINFO[39m:     127.0.0.1:35104 - "[1mGET /online HTTP/1.1[22m" [32m200 OK
[32mINFO[39m:     127.0.0.1:35118 - "[1mGET /online HTTP/1.1[22m" [32m200 OK
[32mINFO[39m:     127.0.0.1:36752 - "[1mGET /online HTTP/1.1[22m" [32m200 OK
[32mINFO[39m:     127.0.0.1:36754 - "[1mGET /online HTTP/1.1[22m" [32m200 OK
[2024-06-07 16:10:10,484][root][INFO] - ccl-y-server;f0:2f:74:96:d6:64-client close
[32mINFO[39m:     Shutting down
[32mINFO[39m:     Finished server process [[36m1971558[39m]
[31mERROR[39m:    Traceback (most recent call last):
  File "/home/ccl/anaconda3/envs/isenv/lib/python3.11/site-packages/starlette/routing.py", line 714, in lifespan
    await receive()
  File "/home/ccl/anaconda3/envs/isenv/lib/python3.11/site-packages/uvicorn/lifespan/on.py", line 137, in receive
    return await self.receive_queue.get()
           ^^^^^^^^^^^^^^^^^^^^^^^^^^^^^^
  File "/home/ccl/anaconda3/envs/isenv/lib/python3.11/asyncio/queues.py", line 158, in get
    await getter
asyncio.exceptions.CancelledError